Workbook

Sheet Raw Data
A1: Name | B1: Country | C1: Users | D1: Purpose | E1: Perigee_km | F1: Apogee_km | G1: Inclination_deg | H1: Period_min | I1: Launch_Mass_kg | K1: Source citation: | L1: UCS Satellite Database — https://www.ucs.org/resources/satellite-database (same dataset as Activity 1 & 2)
A2: Starlink-5792 | B2: USA | C2: Commercial | D2: Communications | E2: 565 | F2: 567 | G2: 43 | H2: 95.8 | I2: 290
A3: Starlink-5053 | B3: USA | C3: Commercial | D3: Communications | E3: 539 | F3: 541 | G3: 53 | H3: 95.4 | I3: 260
A4: BRO-8 | B4: France | C4: Commercial | D4: Earth Observation | E4: 520 | F4: 533 | G4: 97.5 | H4: 95 | I4: 10
A5: EKS-4 (Integrated Space System, Cosmos 2546, Tundra 14L) | B5: Russia | C5: Military | D5: Earth Observation | E5: 1659 | F5: 38503 | G5: 63.8 | H5: 713.9
A6: OneWeb-0359 | B6: United Kingdom | C6: Commercial | D6: Communications | E6: 600 | F6: 610 | G6: 87.4 | H6: 96.75 | I6: 148
A7: OneWeb-0632 | B7: United Kingdom | C7: Commercial | D7: Communications | E7: 733 | F7: 738 | G7: 87.1 | H7: 99.4 | I7: 148
A8: OneWeb-0361 | B8: United Kingdom | C8: Commercial | D8: Communications | E8: 600 | F8: 610 | G8: 87.4 | H8: 96.75 | I8: 148
A9: Starlink-4431 | B9: USA | C9: Commercial | D9: Communications | E9: 562 | F9: 564 | G9: 53.2 | H9: 95.9 | I9: 260
A10: SLDCOM-3 (Satellite Launch Dispenser Communications System) (USA 119) | B10: USA | C10: Military | D10: Communications | E10: 1200 | F10: 11600 | G10: 63.4 | H10: 240
A11: KSM-1B (Kleos Scouting Mission 1B) | B11: Luxembourg | C11: Commercial | D11: Earth Observation | E11: 562 | F11: 575 | G11: 36.9 | H11: 96.1
A12: OneWeb-0456 | B12: United Kingdom | C12: Commercial | D12: Communications | E12: 590 | F12: 600 | G12: 87.4 | H12: 96.4 | I12: 148
A13: Starlink-5283 | B13: USA | C13: Commercial | D13: Communications | E13: 580 | F13: 583 | G13: 70 | H13: 96.2 | I13: 290
A14: Starlink-1330 | B14: USA | C14: Commercial | D14: Communications | E14: 550 | F14: 551 | G14: 53.1 | H14: 95.6 | I14: 227
A15: Starlink-4215 | B15: USA | C15: Commercial | D15: Communications | E15: 538 | F15: 541 | G15: 53.2 | H15: 95.4 | I15: 260
A16: Starlink-1970 | B16: USA | C16: Commercial | D16: Communications | E16: 548 | F16: 561 | G16: 53 | H16: 95.6 | I16: 260
A17: IRNSS-1F (Indian Regional Navigation Satellite System) | B17: India | C17: Government | D17: Navigation/Regional Positioning | E17: 35700 | F17: 35874 | G17: 5.09 | H17: 1436.13 | I17: 1425
A18: Starlink-2037 | B18: USA | C18: Commercial | D18: Communications | E18: 548 | F18: 561 | G18: 53 | H18: 95.6 | I18: 260
A19: Starlink-5156 | B19: USA | C19: Commercial | D19: Communications | E19: 539 | F19: 541 | G19: 53 | H19: 95.4 | I19: 260
A20: Starlink-2081 | B20: USA | C20: Commercial | D20: Communications | E20: 548 | F20: 561 | G20: 53 | H20: 95.6 | I20: 260
A21: Globalstar M072 (Globalstar 72) | B21: USA | C21: Commercial | D21: Communications | E21: 1412 | F21: 1416 | G21: 52 | H21: 114.1 | I21: 450
A22: AEHF-6 (Advanced Extremely High Frequency satellite-6, USA 298) | B22: USA | C22: Military | D22: Communications | E22: 35780 | F22: 35780 | G22: 0 | H22: 1436 | I22: 6169
A23: Starlink-2461 | B23: USA | C23: Commercial | D23: Communications | E23: 260 | F23: 280 | G23: 53 | H23: 95.6 | I23: 260
... A193: Shiyan 1 (SY 1, Tansuo 1, Experimental Satellite 1) | B193: China | C193: Government | D193: Earth Observation | E193: 586 | F193: 601 | G193: 97.5 | H193: 96.6 | I193: 204
A194: Shiyan 7 (SY7, Experimental Satellite 7) | B194: China | C194: Military | D194: Technology Development | E194: 668 | F194: 672 | G194: 98.06 | H194: 98.15
A195: Starlink-4209 | B195: USA | C195: Commercial | D195: Communications | E195: 538 | F195: 541 | G195: 53.2 | H195: 95.4 | I195: 260
A196: OneWeb-0191 | B196: United Kingdom | C196: Commercial | D196: Communications | E196: 1215 | F196: 1220 | G196: 87.4 | H196: 93.5 | I196: 148
A197: Apstar 7 | B197: China | C197: Commercial | D197: Communications | E197: 35864 | F197: 35874 | G197: 0.03 | H197: 1440.31 | I197: 5054
A198: OneWeb-0520 | B198: United Kingdom | C198: Commercial | D198: Communications | E198: 655 | F198: 670 | G198: 86.9 | H198: 98 | I198: 148
A199: Jilin-1 GaoFen 03D-34 | B199: China | C199: Commercial | D199: Earth Observation | E199: 491 | F199: 496 | G199: 97.4 | H199: 94.5 | I199: 42
A200: Lemur-2 SpecialK | B200: USA | C200: Commercial | D200: Earth Observation | E200: 608 | F200: 612 | G200: 97.8 | H200: 94.5 | I200: 10
A201: Starlink-4765 | B201: USA | C201: Commercial | D201: Communications | E201: 539 | F201: 541 | G201: 53 | H201: 95.4 | I201: 260
A202: Starlink-1080 | B202: USA | C202: Commercial | D202: Communications | E202: 549 | F202: 551 | G202: 53 | H202: 90.4 | I202: 227
A203: Starlink-2321 | B203: USA | C203: Commercial | D203: Communications | E203: 548 | F203: 561 | G203: 53 | H203: 95.6 | I203: 260
A204: Starlink-4208 | B204: USA | C204: Commercial | D204: Communications | E204: 538 | F204: 541 | G204: 53.2 | H204: 95.4 | I204: 260
A205: Beesat-8 (Berlin Experimental and Educational Satellite-8) | B205: Germany | C205: Civil | D205: Technology Demonstration | E205: 535 | F205: 556 | G205: 97.6 | H205: 95.5 | I205: 1
A206: INSAT 3DR (Indian National Satellite) | B206: India | C206: Government | D206: Earth Observation | E206: 35722 | F206: 35851 | G206: 0.03 | H206: 1436.1 | I206: 2200
... A301: Starlink-4030 | B301: USA | C301: Commercial | D301: Communications | E301: 538 | F301: 541 | G301: 53.2 | H301: 95.4 | I301: 260
A302: Yaogan 30-2-2 (Remote Sensing Satellite 30-2-2) | B302: China | C302: Military | D302: Earth Observation | E302: 589 | F302: 603 | G302: 35 | H302: 96.6
A303: Starlink-5532 | B303: USA | C303: Commercial | D303: Communications | E303: 577 | F303: 581 | G303: 70 | H303: 96.1 | I303: 290
...

Sheet Central Tendency & Dispersion
A1: Dataset: reused from Activity 1 & 2 (allowed per assignment instructions, condition (i) OR clause). Source: UCS Satellite Database — https://www.ucs.org/resources/satellite-database (1000-row random sample, "Raw Data" tab). All statistics below are live formulas computed directly from that range. | N1: Country (unique) | O1: Count | P1: Rank (tie-broken) | Q1: Users (unique) | R1: Count | S1: Rank (tie-broken) | T1: Purpose (unique) | U1: Count | V1: Rank (tie-broken) | X1: IQR Outlier Fences (used to build the histogram bins in each "Plot of Variable" tab). Lower Limit = Q1 - 1.5xIQR, Upper Limit = Q3 + 1.5xIQR. Any value outside these limits is a statistical outlier and is shown as its own bin at each end of the histogram, instead of being silently absorbed into the middle bins.
N2: Algeria | O2: =COUNTIF('Raw Data'!$B$2:$B$1001,N2) -> 1 | P2: =RANK(O2,$O$2:$O$54,0)+COUNTIF($O$2:O2,O2)-1 -> 27 | Q2: Civil | R2: =COUNTIF('Raw Data'!$C$2:$C$1001,Q2) -> 33 | S2: =RANK(R2,$R$2:$R$13,0)+COUNTIF($R$2:R2,R2)-1 -> 4 | T2: Communications | U2: =COUNTIF('Raw Data'!$D$2:$D$1001,T2) -> 704 | V2: =RANK(U2,$U$2:$U$18,0)+COUNTIF($U$2:U2,U2)-1 -> 1
A3: Variable | B3: Type | C3: Mean | D3: Median | E3: Mode | F3: Reason (Central Tendency) | G3: Range | H3: Variance | I3: Std Dev | J3: IQR / IQV | K3: Reason (Dispersion) | L3: Chart | N3: Argentina | O3: =COUNTIF('Raw Data'!$B$2:$B$1001,N3) -> 8 | P3: =RANK(O3,$O$2:$O$54,0)+COUNTIF($O$2:O3,O3)-1 -> 9 | Q3: Civil/Government | R3: =COUNTIF('Raw Data'!$C$2:$C$1001,Q3) -> 1 | S3: =RANK(R3,$R$2:$R$13,0)+COUNTIF($R$2:R3,R3)-1 -> 10 | T3: Communications/Maritime Tracking | U3: =COUNTIF('Raw Data'!$D$2:$D$1001,T3) -> 2 | V3: =RANK(U3,$U$2:$U$18,0)+COUNTIF($U$2:U3,U3)-1 -> 9 | X3: Variable | Y3: Q1 | Z3: Q3 | AA3: IQR | AB3: Lower Limit (Q1 - 1.5xIQR) | AC3: Upper Limit (Q3 + 1.5xIQR) | AD3: Count Below Lower | AE3: Count Above Upper | AF3: % Flagged as Outliers
A4: Perigee (km) | B4: Numerical | C4: =AVERAGE('Raw Data'!$E$2:$E$1001) -> 4281.8148 | D4: =MEDIAN('Raw Data'!$E$2:$E$1001) -> 548 | E4: =MODE('Raw Data'!$E$2:$E$1001) -> 548 | F4: Mean is the arithmetic average of Perigee (km). Where the mean and median (columns C/D) differ noticeably, it signals skew from outliers, in which case median is the more representative typical value. | G4: =MAX('Raw Data'!$E$2:$E$1001)-MIN('Raw Data'!$E$2:$E$1001) -> 37632 | H4: =_xlfn.VAR.S('Raw Data'!$E$2:$E$1001) -> 1.0985304e+08 | I4: =_xlfn.STDEV.S('Raw Data'!$E$2:$E$1001) -> 10481.08 | J4: =QUARTILE('Raw Data'!$E$2:$E$1001,3)-QUARTILE('Raw Data'!$E$2:$E$1001,1) -> 84 | K4: Range and standard deviation are shown, but since this variable is right-skewed with outliers, IQR (spread of the middle 50%, columns G-J) is the most reliable dispersion measure — it is not dragged around by extreme values the way range and standard deviation are. The exact Lower/Upper Limit and outlier counts are in the "IQR Outlier Fences" table (columns X-AF) on this sheet, and are used directly to build the bins in the matching "Plot of Variable" tab. | L4: See 'Plot of Variable_1' tab for visualization | N4: Australia | O4: =COUNTIF('Raw Data'!$B$2:$B$1001,N4) -> 4 | P4: =RANK(O4,$O$2:$O$54,0)+COUNTIF($O$2:O4,O4)-1 -> 13 | Q4: Civil/Military | R4: =COUNTIF('Raw Data'!$C$2:$C$1001,Q4) -> 1 | S4: =RANK(R4,$R$2:$R$13,0)+COUNTIF($R$2:R4,R4)-1 -> 11 | T4: Earth Observation | U4: =COUNTIF('Raw Data'!$D$2:$D$1001,T4) -> 174 | V4: =RANK(U4,$U$2:$U$18,0)+COUNTIF($U$2:U4,U4)-1 -> 2 | X4: =A4 -> Perigee (km) | Y4: =QUARTILE('Raw Data'!$E$2:$E$1001,1) -> 521 | Z4: =QUARTILE('Raw Data'!$E$2:$E$1001,3) -> 605 | AA4: =J4 -> 84 | AB4: =Y4-1.5*AA4 -> 395 | AC4: =Z4+1.5*AA4 -> 731 | AD4: =COUNTIFS('Raw Data'!$E$2:$E$1001,"<"&AB4,'Raw Data'!$E$2:$E$1001,"<>") -> 112 | AE4: =COUNTIFS('Raw Data'!$E$2:$E$1001,">"&AC4,'Raw Data'!$E$2:$E$1001,"<>") -> 207 | AF4: =(AD4+AE4)/COUNT('Raw Data'!$E$2:$E$1001) -> 0.31931932
A5: Apogee (km) | B5: Numerical | C5: =AVERAGE('Raw Data'!$F$2:$F$1001) -> 5350.7077 | D5: =MEDIAN('Raw Data'!$F$2:$F$1001) -> 561 | E5: =MODE('Raw Data'!$F$2:$F$1001) -> 541 | F5: Mean is the arithmetic average of Apogee (km). Where the mean and median (columns C/D) differ noticeably, it signals skew from outliers, in which case median is the more representative typical value. | G5: =MAX('Raw Data'!$F$2:$F$1001)-MIN('Raw Data'!$F$2:$F$1001) -> 353648 | H5: =_xlfn.VAR.S('Raw Data'!$F$2:$F$1001) -> 3.4278606e+08 | I5: =_xlfn.STDEV.S('Raw Data'!$F$2:$F$1001) -> 18514.482 | J5: =QUARTILE('Raw Data'!$F$2:$F$1001,3)-QUARTILE('Raw Data'!$F$2:$F$1001,1) -> 88.5 | K5: Range and standard deviation are shown, but since this variable is right-skewed with outliers, IQR (spread of the middle 50%, columns G-J) is the most reliable dispersion measure — it is not dragged around by extreme values the way range and standard deviation are. The exact Lower/Upper Limit and outlier counts are in the "IQR Outlier Fences" table (columns X-AF) on this sheet, and are used directly to build the bins in the matching "Plot of Variable" tab. | L5: See 'Plot of Variable_2' tab for visualization | N5: Azerbaijan | O5: =COUNTIF('Raw Data'!$B$2:$B$1001,N5) -> 1 | P5: =RANK(O5,$O$2:$O$54,0)+COUNTIF($O$2:O5,O5)-1 -> 28 | Q5: Commercial | R5: =COUNTIF('Raw Data'!$C$2:$C$1001,Q5) -> 788 | S5: =RANK(R5,$R$2:$R$13,0)+COUNTIF($R$2:R5,R5)-1 -> 1 | T5: Earth Observation | U5: =COUNTIF('Raw Data'!$D$2:$D$1001,T5) -> 1 | V5: =RANK(U5,$U$2:$U$18,0)+COUNTIF($U$2:U5,U5)-1 -> 13 | X5: =A5 -> Apogee (km) | Y5: =QUARTILE('Raw Data'!$F$2:$F$1001,1) -> 536 | Z5: =QUARTILE('Raw Data'!$F$2:$F$1001,3) -> 624.5 | AA5: =J5 -> 88.5 | AB5: =Y5-1.5*AA5 -> 403.25 | AC5: =Z5+1.5*AA5 -> 757.25 | AD5: =COUNTIFS('Raw Data'!$F$2:$F$1001,"<"&AB5,'Raw Data'!$F$2:$F$1001,"<>") -> 106 | AE5: =COUNTIFS('Raw Data'!$F$2:$F$1001,">"&AC5,'Raw Data'!$F$2:$F$1001,"<>") -> 209 | AF5: =(AD5+AE5)/COUNT('Raw Data'!$F$2:$F$1001) -> 0.31531532
A6: Inclination (deg) | B6: Numerical | C6: =AVERAGE('Raw Data'!$G$2:$G$1001) -> 61.4101 | D6: =MEDIAN('Raw Data'!$G$2:$G$1001) -> 53.2 | E6: =MODE('Raw Data'!$G$2:$G$1001) -> 53 | F6: Mean is the arithmetic average of Inclination (deg). Where the mean and median (columns C/D) differ noticeably, it signals skew from outliers, in which case median is the more representative typical value. | G6: =MAX('Raw Data'!$G$2:$G$1001)-MIN('Raw Data'!$G$2:$G$1001) -> 141.12 | H6: =_xlfn.VAR.S('Raw Data'!$G$2:$G$1001) -> 837.0205 | I6: =_xlfn.STDEV.S('Raw Data'!$G$2:$G$1001) -> 28.931307 | J6: =QUARTILE('Raw Data'!$G$2:$G$1001,3)-QUARTILE('Raw Data'!$G$2:$G$1001,1) -> 34.9 | K6: Range and standard deviation are shown, but since this variable is right-skewed with outliers, IQR (spread of the middle 50%, columns G-J) is the most reliable dispersion measure — it is not dragged around by extreme values the way range and standard deviation are. The exact Lower/Upper Limit and outlier counts are in the "IQR Outlier Fences" table (columns X-AF) on this sheet, and are used directly to build the bins in the matching "Plot of Variable" tab. | L6: See 'Plot of Variable_3' tab for visualization | N6: Bangladesh | O6: =COUNTIF('Raw Data'!$B$2:$B$1001,N6) -> 1 | P6: =RANK(O6,$O$2:$O$54,0)+COUNTIF($O$2:O6,O6)-1 -> 29 | Q6: Government | R6: =COUNTIF('Raw Data'!$C$2:$C$1001,Q6) -> 80 | S6: =RANK(R6,$R$2:$R$13,0)+COUNTIF($R$2:R6,R6)-1 -> 2 | T6: Earth Observation/Technology Development | U6: =COUNTIF('Raw Data'!$D$2:$D$1001,T6) -> 2 | V6: =RANK(U6,$U$2:$U$18,0)+COUNTIF($U$2:U6,U6)-1 -> 10 | X6: =A6 -> Inclination (deg) | Y6: =QUARTILE('Raw Data'!$G$2:$G$1001,1) -> 53 | Z6: =QUARTILE('Raw Data'!$G$2:$G$1001,3) -> 87.9 | AA6: =J6 -> 34.9 | AB6: =Y6-1.5*AA6 -> 0.65 | AC6: =Z6+1.5*AA6 -> 140.25 | AD6: =COUNTIFS('Raw Data'!$G$2:$G$1001,"<"&AB6,'Raw Data'!$G$2:$G$1001,"<>") -> 86 | AE6: =COUNTIFS('Raw Data'!$G$2:$G$1001,">"&AC6,'Raw Data'!$G$2:$G$1001,"<>") -> 1 | AF6: =(AD6+AE6)/COUNT('Raw Data'!$G$2:$G$1001) -> 0.087
A7: Period (min) | B7: Numerical | C7: =AVERAGE('Raw Data'!$H$2:$H$1001) -> 254.48486 | D7: =MEDIAN('Raw Data'!$H$2:$H$1001) -> 95.6 | E7: =MODE('Raw Data'!$H$2:$H$1001) -> 95.6 | F7: Mean is the arithmetic average of Period (min). Where the mean and median (columns C/D) differ noticeably, it signals skew from outliers, in which case median is the more representative typical value. | G7: =MAX('Raw Data'!$H$2:$H$1001)-MIN('Raw Data'!$H$2:$H$1001) -> 8671 | H7: =_xlfn.VAR.S('Raw Data'!$H$2:$H$1001) -> 256982.81 | I7: =_xlfn.STDEV.S('Raw Data'!$H$2:$H$1001) -> 506.93472 | J7: =QUARTILE('Raw Data'!$H$2:$H$1001,3)-QUARTILE('Raw Data'!$H$2:$H$1001,1) -> 1.75 | K7: Range and standard deviation are shown, but since this variable is right-skewed with outliers, IQR (spread of the middle 50%, columns G-J) is the most reliable dispersion measure — it is not dragged around by extreme values the way range and standard deviation are. The exact Lower/Upper Limit and outlier counts are in the "IQR Outlier Fences" table (columns X-AF) on this sheet, and are used directly to build the bins in the matching "Plot of Variable" tab. | L7: See 'Plot of Variable_4' tab for visualization | N7: Belarus | O7: =COUNTIF('Raw Data'!$B$2:$B$1001,N7) -> 1 | P7: =RANK(O7,$O$2:$O$54,0)+COUNTIF($O$2:O7,O7)-1 -> 30 | Q7: Government/Civil | R7: =COUNTIF('Raw Data'!$C$2:$C$1001,Q7) -> 6 | S7: =RANK(R7,$R$2:$R$13,0)+COUNTIF($R$2:R7,R7)-1 -> 7 | T7: Earth Science | U7: =COUNTIF('Raw Data'!$D$2:$D$1001,T7) -> 2 | V7: =RANK(U7,$U$2:$U$18,0)+COUNTIF($U$2:U7,U7)-1 -> 11 | X7: =A7 -> Period (min) | Y7: =QUARTILE('Raw Data'!$H$2:$H$1001,1) -> 95 | Z7: =QUARTILE('Raw Data'!$H$2:$H$1001,3) -> 96.75 | AA7: =J7 -> 1.75 | AB7: =Y7-1.5*AA7 -> 92.375 | AC7: =Z7+1.5*AA7 -> 99.375 | AD7: =COUNTIFS('Raw Data'!$H$2:$H$1001,"<"&AB7,'Raw Data'!$H$2:$H$1001,"<>") -> 94 | AE7: =COUNTIFS('Raw Data'!$H$2:$H$1001,">"&AC7,'Raw Data'!$H$2:$H$1001,"<>") -> 196 | AF7: =(AD7+AE7)/COUNT('Raw Data'!$H$2:$H$1001) -> 0.29145729
A8: Launch Mass (kg) | B8: Numerical | C8: =AVERAGE('Raw Data'!$I$2:$I$1001) -> 739.52182 | D8: =MEDIAN('Raw Data'!$I$2:$I$1001) -> 260 | E8: =MODE('Raw Data'!$I$2:$I$1001) -> 260 | F8: Mean is the arithmetic average of Launch Mass (kg). Where the mean and median (columns C/D) differ noticeably, it signals skew from outliers, in which case median is the more representative typical value. | G8: =MAX('Raw Data'!$I$2:$I$1001)-MIN('Raw Data'!$I$2:$I$1001) -> 19999 | H8: =_xlfn.VAR.S('Raw Data'!$I$2:$I$1001) -> 2589818.2 | I8: =_xlfn.STDEV.S('Raw Data'!$I$2:$I$1001) -> 1609.2912 | J8: =QUARTILE('Raw Data'!$I$2:$I$1001,3)-QUARTILE('Raw Data'!$I$2:$I$1001,1) -> 142 | K8: Range and standard deviation are shown, but since this variable is right-skewed with outliers, IQR (spread of the middle 50%, columns G-J) is the most reliable dispersion measure — it is not dragged around by extreme values the way range and standard deviation are. The exact Lower/Upper Limit and outlier counts are in the "IQR Outlier Fences" table (columns X-AF) on this sheet, and are used directly to build the bins in the matching "Plot of Variable" tab. | L8: See 'Plot of Variable_5' tab for visualization | N8: Brazil | O8: =COUNTIF('Raw Data'!$B$2:$B$1001,N8) -> 4 | P8: =RANK(O8,$O$2:$O$54,0)+COUNTIF($O$2:O8,O8)-1 -> 14 | Q8: Government/Commercial | R8: =COUNTIF('Raw Data'!$C$2:$C$1001,Q8) -> 12 | S8: =RANK(R8,$R$2:$R$13,0)+COUNTIF($R$2:R8,R8)-1 -> 5 | T8: Earth Science/Earth Observation | U8: =COUNTIF('Raw Data'!$D$2:$D$1001,T8) -> 1 | V8: =RANK(U8,$U$2:$U$18,0)+COUNTIF($U$2:U8,U8)-1 -> 14 | X8: =A8 -> Launch Mass (kg) | Y8: =QUARTILE('Raw Data'!$I$2:$I$1001,1) -> 148 | Z8: =QUARTILE('Raw Data'!$I$2:$I$1001,3) -> 290 | AA8: =J8 -> 142 | AB8: =Y8-1.5*AA8 -> -65 | AC8: =Z8+1.5*AA8 -> 503 | AD8: =COUNTIFS('Raw Data'!$I$2:$I$1001,"<"&AB8,'Raw Data'!$I$2:$I$1001,"<>") -> 0 | AE8: =COUNTIFS('Raw Data'!$I$2:$I$1001,">"&AC8,'Raw Data'!$I$2:$I$1001,"<>") -> 175 | AF8: =(AD8+AE8)/COUNT('Raw Data'!$I$2:$I$1001) -> 0.18097208
A9: Country | B9: Categorical | C9: N/A | D9: N/A | E9: {=INDEX(N2:N54,MATCH(MAX(O2:O54),O2:O54,0))} -> USA | F9: Mean and median are undefined for a categorical variable since its values are labels, not numbers. Mode (column E) is the only valid central tendency measure — it is calculated by finding the category with the highest COUNTIF count among all unique values (see helper table, columns further right). | G9: N/A | H9: N/A | I9: N/A | J9: =(COUNTA(N2:N54)*(SUM(O2:O54)^2-SUMSQ(O2:O54)))/(SUM(O2:O54)^2*(COUNTA(N2:N54)-1)) -> 0.54790177 | K9: Range/variance/std don't apply to categories. Instead, the Index of Qualitative Variation (IQV, column J) measures how evenly the categories are spread — near 1 means evenly represented, near 0 means one category dominates. IQV here is computed live from the COUNTIF-based helper table using k (number of categories), n (total count), and the sum of squared counts. | L9: See 'Plot of Variable_6' tab for visualization | N9: Bulgaria | O9: =COUNTIF('Raw Data'!$B$2:$B$1001,N9) -> 1 | P9: =RANK(O9,$O$2:$O$54,0)+COUNTIF($O$2:O9,O9)-1 -> 31 | Q9: Government/Military | R9: =COUNTIF('Raw Data'!$C$2:$C$1001,Q9) -> 1 | S9: =RANK(R9,$R$2:$R$13,0)+COUNTIF($R$2:R9,R9)-1 -> 12 | T9: Meteorological | U9: =COUNTIF('Raw Data'!$D$2:$D$1001,T9) -> 2 | V9: =RANK(U9,$U$2:$U$18,0)+COUNTIF($U$2:U9,U9)-1 -> 12
A10: Users | B10: Categorical | C10: N/A | D10: N/A | E10: {=INDEX(Q2:Q13,MATCH(MAX(R2:R13),R2:R13,0))} -> Commercial | F10: Mean and median are undefined for a categorical variable since its values are labels, not numbers. Mode (column E) is the only valid central tendency measure — it is calculated by finding the category with the highest COUNTIF count among all unique values (see helper table, columns further right). | G10: N/A | H10: N/A | I10: N/A | J10: =(COUNTA(Q2:Q13)*(SUM(R2:R13)^2-SUMSQ(R2:R13)))/(SUM(R2:R13)^2*(COUNTA(Q2:Q13)-1)) -> 0.40127564 | K10: Range/variance/std don't apply to categories. Instead, the Index of Qualitative Variation (IQV, column J) measures how evenly the categories are spread — near 1 means evenly represented, near 0 means one category dominates. IQV here is computed live from the COUNTIF-based helper table using k (number of categories), n (total count), and the sum of squared counts. | L10: See 'Plot of Variable_7' tab for visualization | N10: Canada | O10: =COUNTIF('Raw Data'!$B$2:$B$1001,N10) -> 11 | P10: =RANK(O10,$O$2:$O$54,0)+COUNTIF($O$2:O10,O10)-1 -> 5 | Q10: Military | R10: =COUNTIF('Raw Data'!$C$2:$C$1001,Q10) -> 58 | S10: =RANK(R10,$R$2:$R$13,0)+COUNTIF($R$2:R10,R10)-1 -> 3 | T10: Mission Extension Technology | U10: =COUNTIF('Raw Data'!$D$2:$D$1001,T10) -> 1 | V10: =RANK(U10,$U$2:$U$18,0)+COUNTIF($U$2:U10,U10)-1 -> 15
A11: Purpose | B11: Categorical | C11: N/A | D11: N/A | E11: {=INDEX(T2:T18,MATCH(MAX(U2:U18),U2:U18,0))} -> Communications | F11: Mean and median are undefined for a categorical variable since its values are labels, not numbers. Mode (column E) is the only valid central tendency measure — it is calculated by finding the category with the highest COUNTIF count among all unique values (see helper table, columns further right). | G11: N/A | H11: N/A | I11: N/A | J11: =(COUNTA(T2:T18)*(SUM(U2:U18)^2-SUMSQ(U2:U18)))/(SUM(U2:U18)^2*(COUNTA(T2:T18)-1)) -> 0.4997915 | K11: Range/variance/std don't apply to categories. Instead, the Index of Qualitative Variation (IQV, column J) measures how evenly the categories are spread — near 1 means evenly represented, near 0 means one category dominates. IQV here is computed live from the COUNTIF-based helper table using k (number of categories), n (total count), and the sum of squared counts. | L11: See 'Plot of Variable_8' tab for visualization | N11: China | O11: =COUNTIF('Raw Data'!$B$2:$B$1001,N11) -> 77 | P11: =RANK(O11,$O$2:$O$54,0)+COUNTIF($O$2:O11,O11)-1 -> 3 | Q11: Military/Civil | R11: =COUNTIF('Raw Data'!$C$2:$C$1001,Q11) -> 2 | S11: =RANK(R11,$R$2:$R$13,0)+COUNTIF($R$2:R11,R11)-1 -> 9 | T11: Navigation/Global Positioning | U11: =COUNTIF('Raw Data'!$D$2:$D$1001,T11) -> 20 | V11: =RANK(U11,$U$2:$U$18,0)+COUNTIF($U$2:U11,U11)-1 -> 4
N12: ESA | O12: =COUNTIF('Raw Data'!$B$2:$B$1001,N12) -> 7 | P12: =RANK(O12,$O$2:$O$54,0)+COUNTIF($O$2:O12,O12)-1 -> 11 | Q12: Military/Commercial | R12: =COUNTIF('Raw Data'!$C$2:$C$1001,Q12) -> 12 | S12: =RANK(R12,$R$2:$R$13,0)+COUNTIF($R$2:R12,R12)-1 -> 6 | T12: Navigation/Regional Positioning | U12: =COUNTIF('Raw Data'!$D$2:$D$1001,T12) -> 3 | V12: =RANK(U12,$U$2:$U$18,0)+COUNTIF($U$2:U12,U12)-1 -> 7
N13: Egypt | O13: =COUNTIF('Raw Data'!$B$2:$B$1001,N13) -> 1 | P13: =RANK(O13,$O$2:$O$54,0)+COUNTIF($O$2:O13,O13)-1 -> 32 | Q13: Military/Government | R13: =COUNTIF('Raw Data'!$C$2:$C$1001,Q13) -> 6 | S13: =RANK(R13,$R$2:$R$13,0)+COUNTIF($R$2:R13,R13)-1 -> 8 | T13: Satellite Positioning | U13: =COUNTIF('Raw Data'!$D$2:$D$1001,T13) -> 1 | V13: =RANK(U13,$U$2:$U$18,0)+COUNTIF($U$2:U13,U13)-1 -> 16
N14: Finland | O14: =COUNTIF('Raw Data'!$B$2:$B$1001,N14) -> 3 | P14: =RANK(O14,$O$2:$O$54,0)+COUNTIF($O$2:O14,O14)-1 -> 17 | T14: Space Science | U14: =COUNTIF('Raw Data'!$D$2:$D$1001,T14) -> 18 | V14: =RANK(U14,$U$2:$U$18,0)+COUNTIF($U$2:U14,U14)-1 -> 5
N15: France | O15: =COUNTIF('Raw Data'!$B$2:$B$1001,N15) -> 4 | P15: =RANK(O15,$O$2:$O$54,0)+COUNTIF($O$2:O15,O15)-1 -> 15 | T15: Surveillance | U15: =COUNTIF('Raw Data'!$D$2:$D$1001,T15) -> 3 | V15: =RANK(U15,$U$2:$U$18,0)+COUNTIF($U$2:U15,U15)-1 -> 8
N16: France/Belgium/Sweden | O16: =COUNTIF('Raw Data'!$B$2:$B$1001,N16) -> 1 | P16: =RANK(O16,$O$2:$O$54,0)+COUNTIF($O$2:O16,O16)-1 -> 33 | T16: Technology Demonstration | U16: =COUNTIF('Raw Data'!$D$2:$D$1001,T16) -> 12 | V16: =RANK(U16,$U$2:$U$18,0)+COUNTIF($U$2:U16,U16)-1 -> 6
N17: France/Israel | O17: =COUNTIF('Raw Data'!$B$2:$B$1001,N17) -> 1 | P17: =RANK(O17,$O$2:$O$54,0)+COUNTIF($O$2:O17,O17)-1 -> 34 | T17: Technology Development | U17: =COUNTIF('Raw Data'!$D$2:$D$1001,T17) -> 53 | V17: =RANK(U17,$U$2:$U$18,0)+COUNTIF($U$2:U17,U17)-1 -> 3
N18: Germany | O18: =COUNTIF('Raw Data'!$B$2:$B$1001,N18) -> 5 | P18: =RANK(O18,$O$2:$O$54,0)+COUNTIF($O$2:O18,O18)-1 -> 12 | T18: Unknown | U18: =COUNTIF('Raw Data'!$D$2:$D$1001,T18) -> 1 | V18: =RANK(U18,$U$2:$U$18,0)+COUNTIF($U$2:U18,U18)-1 -> 17
N19: India | O19: =COUNTIF('Raw Data'!$B$2:$B$1001,N19) -> 11 | P19: =RANK(O19,$O$2:$O$54,0)+COUNTIF($O$2:O19,O19)-1 -> 6
N20: Indonesia | O20: =COUNTIF('Raw Data'!$B$2:$B$1001,N20) -> 1 | P20: =RANK(O20,$O$2:$O$54,0)+COUNTIF($O$2:O20,O20)-1 -> 35
N21: Israel | O21: =COUNTIF('Raw Data'!$B$2:$B$1001,N21) -> 2 | P21: =RANK(O21,$O$2:$O$54,0)+COUNTIF($O$2:O21,O21)-1 -> 22
N22: Italy | O22: =COUNTIF('Raw Data'!$B$2:$B$1001,N22) -> 3 | P22: =RANK(O22,$O$2:$O$54,0)+COUNTIF($O$2:O22,O22)-1 -> 18
N23: Japan | O23: =COUNTIF('Raw Data'!$B$2:$B$1001,N23) -> 11 | P23: =RANK(O23,$O$2:$O$54,0)+COUNTIF($O$2:O23,O23)-1 -> 7
N24: Jordan | O24: =COUNTIF('Raw Data'!$B$2:$B$1001,N24) -> 1 | P24: =RANK(O24,$O$2:$O$54,0)+COUNTIF($O$2:O24,O24)-1 -> 36
N25: Kazakhstan | O25: =COUNTIF('Raw Data'!$B$2:$B$1001,N25) -> 1 | P25: =RANK(O25,$O$2:$O$54,0)+COUNTIF($O$2:O25,O25)-1 -> 37
N26: Laos | O26: =COUNTIF('Raw Data'!$B$2:$B$1001,N26) -> 1 | P26: =RANK(O26,$O$2:$O$54,0)+COUNTIF($O$2:O26,O26)-1 -> 38
N27: Lithuania | O27: =COUNTIF('Raw Data'!$B$2:$B$1001,N27) -> 1 | P27: =RANK(O27,$O$2:$O$54,0)+COUNTIF($O$2:O27,O27)-1 -> 39
N28: Luxembourg | O28: =COUNTIF('Raw Data'!$B$2:$B$1001,N28) -> 8 | P28: =RANK(O28,$O$2:$O$54,0)+COUNTIF($O$2:O28,O28)-1 -> 10
N29: Malaysia | O29: =COUNTIF('Raw Data'!$B$2:$B$1001,N29) -> 3 | P29: =RANK(O29,$O$2:$O$54,0)+COUNTIF($O$2:O29,O29)-1 -> 19
N30: Mexico | O30: =COUNTIF('Raw Data'!$B$2:$B$1001,N30) -> 2 | P30: =RANK(O30,$O$2:$O$54,0)+COUNTIF($O$2:O30,O30)-1 -> 23
... N54: Venezuela | O54: =COUNTIF('Raw Data'!$B$2:$B$1001,N54) -> 1 | P54: =RANK(O54,$O$2:$O$54,0)+COUNTIF($O$2:O54,O54)-1 -> 53

Sheet Plot of Variable_1
A1: Perigee (km) — bin range | B1: Count of Satellites | C1: Bin lower (>=) | D1: Bin upper | F1: Lower Limit: | G1: ='Central Tendency & Dispersion'!$AB$4 -> 395 | H1: Upper Limit: | I1: ='Central Tendency & Dispersion'!$AC$4 -> 731 | K1: Eff. Lower: | L1: =MAX($G$1,MIN('Raw Data'!$E$2:$E$1001)) -> 395 | M1: Eff. Upper: | N1: =MIN($I$1,MAX('Raw Data'!$E$2:$E$1001)) -> 731
A2: ="< "&TEXT(D2,"#,##0")&" (below fence)" -> < 395 (below fence) | B2: =COUNTIFS('Raw Data'!$E$2:$E$1001,">="&C2,'Raw Data'!$E$2:$E$1001,"<"&D2) -> 112 | C2: =MIN('Raw Data'!$E$2:$E$1001) -> 150 | D2: =$L$1 -> 395
A3: =TEXT(C3,"#,##0")&"–"&TEXT(D3,"#,##0") -> 395–451 | B3: =COUNTIFS('Raw Data'!$E$2:$E$1001,">="&C3,'Raw Data'!$E$2:$E$1001,"<"&D3) -> 13 | C3: =D2 -> 395 | D3: =$L$1+(1)*($N$1-$L$1)/6 -> 451
A4: =TEXT(C4,"#,##0")&"–"&TEXT(D4,"#,##0") -> 451–507 | B4: =COUNTIFS('Raw Data'!$E$2:$E$1001,">="&C4,'Raw Data'!$E$2:$E$1001,"<"&D4) -> 85 | C4: =D3 -> 451 | D4: =$L$1+(2)*($N$1-$L$1)/6 -> 507
A5: =TEXT(C5,"#,##0")&"–"&TEXT(D5,"#,##0") -> 507–563 | B5: =COUNTIFS('Raw Data'!$E$2:$E$1001,">="&C5,'Raw Data'!$E$2:$E$1001,"<"&D5) -> 403 | C5: =D4 -> 507 | D5: =$L$1+(3)*($N$1-$L$1)/6 -> 563
A6: =TEXT(C6,"#,##0")&"–"&TEXT(D6,"#,##0") -> 563–619 | B6: =COUNTIFS('Raw Data'!$E$2:$E$1001,">="&C6,'Raw Data'!$E$2:$E$1001,"<"&D6) -> 152 | C6: =D5 -> 563 | D6: =$L$1+(4)*($N$1-$L$1)/6 -> 619
A7: =TEXT(C7,"#,##0")&"–"&TEXT(D7,"#,##0") -> 619–675 | B7: =COUNTIFS('Raw Data'!$E$2:$E$1001,">="&C7,'Raw Data'!$E$2:$E$1001,"<"&D7) -> 16 | C7: =D6 -> 619 | D7: =$L$1+(5)*($N$1-$L$1)/6 -> 675
A8: =TEXT(C8,"#,##0")&"–"&TEXT(D8,"#,##0") -> 675–731 | B8: =COUNTIFS('Raw Data'!$E$2:$E$1001,">="&C8,'Raw Data'!$E$2:$E$1001,"<="&D8) -> 11 | C8: =D7 -> 675 | D8: =$N$1 -> 731
A9: ="> "&TEXT(C9,"#,##0")&" (above fence)" -> > 731 (above fence) | B9: =COUNTIFS('Raw Data'!$E$2:$E$1001,">"&C9,'Raw Data'!$E$2:$E$1001,"<="&D9) -> 207 | C9: =$N$1 -> 731 | D9: =MAX('Raw Data'!$E$2:$E$1001) -> 37782
A11: IQR Outlier Fence Summary
A12: Lower Limit (Q1 − 1.5×IQR) | B12: =G1 -> 395
A13: Upper Limit (Q3 + 1.5×IQR) | B13: =I1 -> 731
A14: Count below lower limit | B14: =B2 -> 112
A15: Count above upper limit | B15: =B9 -> 207
A16: % flagged as outliers | B16: =(B2+B9)/SUM(B2:B9) -> 0.31931932

Sheet Plot of Variable_2
A1: Apogee (km) — bin range | B1: Count of Satellites | C1: Bin lower (>=) | D1: Bin upper | F1: Lower Limit: | G1: ='Central Tendency & Dispersion'!$AB$5 -> 403.25 | H1: Upper Limit: | I1: ='Central Tendency & Dispersion'!$AC$5 -> 757.25 | K1: Eff. Lower: | L1: =MAX($G$1,MIN('Raw Data'!$F$2:$F$1001)) -> 403.25 | M1: Eff. Upper: | N1: =MIN($I$1,MAX('Raw Data'!$F$2:$F$1001)) -> 757.25
A2: ="< "&TEXT(D2,"#,##0")&" (below fence)" -> < 403 (below fence) | B2: =COUNTIFS('Raw Data'!$F$2:$F$1001,">="&C2,'Raw Data'!$F$2:$F$1001,"<"&D2) -> 106 | C2: =MIN('Raw Data'!$F$2:$F$1001) -> 150 | D2: =$L$1 -> 403.25
A3: =TEXT(C3,"#,##0")&"–"&TEXT(D3,"#,##0") -> 403–462 | B3: =COUNTIFS('Raw Data'!$F$2:$F$1001,">="&C3,'Raw Data'!$F$2:$F$1001,"<"&D3) -> 16 | C3: =D2 -> 403.25 | D3: =$L$1+(1)*($N$1-$L$1)/6 -> 462.25
A4: =TEXT(C4,"#,##0")&"–"&TEXT(D4,"#,##0") -> 462–521 | B4: =COUNTIFS('Raw Data'!$F$2:$F$1001,">="&C4,'Raw Data'!$F$2:$F$1001,"<"&D4) -> 79 | C4: =D3 -> 462.25 | D4: =$L$1+(2)*($N$1-$L$1)/6 -> 521.25
A5: =TEXT(C5,"#,##0")&"–"&TEXT(D5,"#,##0") -> 521–580 | B5: =COUNTIFS('Raw Data'!$F$2:$F$1001,">="&C5,'Raw Data'!$F$2:$F$1001,"<"&D5) -> 463 | C5: =D4 -> 521.25 | D5: =$L$1+(3)*($N$1-$L$1)/6 -> 580.25
A6: =TEXT(C6,"#,##0")&"–"&TEXT(D6,"#,##0") -> 580–639 | B6: =COUNTIFS('Raw Data'!$F$2:$F$1001,">="&C6,'Raw Data'!$F$2:$F$1001,"<"&D6) -> 93 | C6: =D5 -> 580.25 | D6: =$L$1+(4)*($N$1-$L$1)/6 -> 639.25
A7: =TEXT(C7,"#,##0")&"–"&TEXT(D7,"#,##0") -> 639–698 | B7: =COUNTIFS('Raw Data'!$F$2:$F$1001,">="&C7,'Raw Data'!$F$2:$F$1001,"<"&D7) -> 17 | C7: =D6 -> 639.25 | D7: =$L$1+(5)*($N$1-$L$1)/6 -> 698.25
A8: =TEXT(C8,"#,##0")&"–"&TEXT(D8,"#,##0") -> 698–757 | B8: =COUNTIFS('Raw Data'!$F$2:$F$1001,">="&C8,'Raw Data'!$F$2:$F$1001,"<="&D8) -> 16 | C8: =D7 -> 698.25 | D8: =$N$1 -> 757.25
A9: ="> "&TEXT(C9,"#,##0")&" (above fence)" -> > 757 (above fence) | B9: =COUNTIFS('Raw Data'!$F$2:$F$1001,">"&C9,'Raw Data'!$F$2:$F$1001,"<="&D9) -> 209 | C9: =$N$1 -> 757.25 | D9: =MAX('Raw Data'!$F$2:$F$1001) -> 353798
A11: IQR Outlier Fence Summary
A12: Lower Limit (Q1 − 1.5×IQR) | B12: =G1 -> 403.25
A13: Upper Limit (Q3 + 1.5×IQR) | B13: =I1 -> 757.25
A14: Count below lower limit | B14: =B2 -> 106
A15: Count above upper limit | B15: =B9 -> 209
A16: % flagged as outliers | B16: =(B2+B9)/SUM(B2:B9) -> 0.31531532

Sheet Plot of Variable_3
A1: Inclination (deg) — bin range | B1: Count of Satellites | C1: Bin lower (>=) | D1: Bin upper | F1: Lower Limit: | G1: ='Central Tendency & Dispersion'!$AB$6 -> 0.65 | H1: Upper Limit: | I1: ='Central Tendency & Dispersion'!$AC$6 -> 140.25 | K1: Eff. Lower: | L1: =MAX($G$1,MIN('Raw Data'!$G$2:$G$1001)) -> 0.65 | M1: Eff. Upper: | N1: =MIN($I$1,MAX('Raw Data'!$G$2:$G$1001)) -> 140.25
A2: ="< "&TEXT(D2,"0.00")&" (below fence)" -> < 0.65 (below fence) | B2: =COUNTIFS('Raw Data'!$G$2:$G$1001,">="&C2,'Raw Data'!$G$2:$G$1001,"<"&D2) -> 86 | C2: =MIN('Raw Data'!$G$2:$G$1001) -> 0 | D2: =$L$1 -> 0.65
A3: =TEXT(C3,"0.00")&"–"&TEXT(D3,"0.00") -> 0.65–23.92 | B3: =COUNTIFS('Raw Data'!$G$2:$G$1001,">="&C3,'Raw Data'!$G$2:$G$1001,"<"&D3) -> 19 | C3: =D2 -> 0.65 | D3: =$L$1+(1)*($N$1-$L$1)/6 -> 23.916667
A4: =TEXT(C4,"0.00")&"–"&TEXT(D4,"0.00") -> 23.92–47.18 | B4: =COUNTIFS('Raw Data'!$G$2:$G$1001,">="&C4,'Raw Data'!$G$2:$G$1001,"<"&D4) -> 83 | C4: =D3 -> 23.916667 | D4: =$L$1+(2)*($N$1-$L$1)/6 -> 47.183333
A5: =TEXT(C5,"0.00")&"–"&TEXT(D5,"0.00") -> 47.18–70.45 | B5: =COUNTIFS('Raw Data'!$G$2:$G$1001,">="&C5,'Raw Data'!$G$2:$G$1001,"<"&D5) -> 478 | C5: =D4 -> 47.183333 | D5: =$L$1+(3)*($N$1-$L$1)/6 -> 70.45
A6: =TEXT(C6,"0.00")&"–"&TEXT(D6,"0.00") -> 70.45–93.72 | B6: =COUNTIFS('Raw Data'!$G$2:$G$1001,">="&C6,'Raw Data'!$G$2:$G$1001,"<"&D6) -> 93 | C6: =D5 -> 70.45 | D6: =$L$1+(4)*($N$1-$L$1)/6 -> 93.716667
A7: =TEXT(C7,"0.00")&"–"&TEXT(D7,"0.00") -> 93.72–116.98 | B7: =COUNTIFS('Raw Data'!$G$2:$G$1001,">="&C7,'Raw Data'!$G$2:$G$1001,"<"&D7) -> 239 | C7: =D6 -> 93.716667 | D7: =$L$1+(5)*($N$1-$L$1)/6 -> 116.98333
A8: =TEXT(C8,"0.00")&"–"&TEXT(D8,"0.00") -> 116.98–140.25 | B8: =COUNTIFS('Raw Data'!$G$2:$G$1001,">="&C8,'Raw Data'!$G$2:$G$1001,"<="&D8) -> 1 | C8: =D7 -> 116.98333 | D8: =$N$1 -> 140.25
A9: ="> "&TEXT(C9,"0.00")&" (above fence)" -> > 140.25 (above fence) | B9: =COUNTIFS('Raw Data'!$G$2:$G$1001,">"&C9,'Raw Data'!$G$2:$G$1001,"<="&D9) -> 1 | C9: =$N$1 -> 140.25 | D9: =MAX('Raw Data'!$G$2:$G$1001) -> 141.12
A11: IQR Outlier Fence Summary
A12: Lower Limit (Q1 − 1.5×IQR) | B12: =G1 -> 0.65
A13: Upper Limit (Q3 + 1.5×IQR) | B13: =I1 -> 140.25
A14: Count below lower limit | B14: =B2 -> 86
A15: Count above upper limit | B15: =B9 -> 1
A16: % flagged as outliers | B16: =(B2+B9)/SUM(B2:B9) -> 0.087

Sheet Plot of Variable_4
A1: Period (min) — bin range | B1: Count of Satellites | C1: Bin lower (>=) | D1: Bin upper | F1: Lower Limit: | G1: ='Central Tendency & Dispersion'!$AB$7 -> 92.375 | H1: Upper Limit: | I1: ='Central Tendency & Dispersion'!$AC$7 -> 99.375 | K1: Eff. Lower: | L1: =MAX($G$1,MIN('Raw Data'!$H$2:$H$1001)) -> 92.375 | M1: Eff. Upper: | N1: =MIN($I$1,MAX('Raw Data'!$H$2:$H$1001)) -> 99.375
A2: ="< "&TEXT(D2,"0.00")&" (below fence)" -> < 92.38 (below fence) | B2: =COUNTIFS('Raw Data'!$H$2:$H$1001,">="&C2,'Raw Data'!$H$2:$H$1001,"<"&D2) -> 94 | C2: =MIN('Raw Data'!$H$2:$H$1001) -> 87 | D2: =$L$1 -> 92.375
A3: =TEXT(C3,"0.00")&"–"&TEXT(D3,"0.00") -> 92.38–93.54 | B3: =COUNTIFS('Raw Data'!$H$2:$H$1001,">="&C3,'Raw Data'!$H$2:$H$1001,"<"&D3) -> 25 | C3: =D2 -> 92.375 | D3: =$L$1+(1)*($N$1-$L$1)/6 -> 93.541667
A4: =TEXT(C4,"0.00")&"–"&TEXT(D4,"0.00") -> 93.54–94.71 | B4: =COUNTIFS('Raw Data'!$H$2:$H$1001,">="&C4,'Raw Data'!$H$2:$H$1001,"<"&D4) -> 108 | C4: =D3 -> 93.541667 | D4: =$L$1+(2)*($N$1-$L$1)/6 -> 94.708333
A5: =TEXT(C5,"0.00")&"–"&TEXT(D5,"0.00") -> 94.71–95.88 | B5: =COUNTIFS('Raw Data'!$H$2:$H$1001,">="&C5,'Raw Data'!$H$2:$H$1001,"<"&D5) -> 417 | C5: =D4 -> 94.708333 | D5: =$L$1+(3)*($N$1-$L$1)/6 -> 95.875
A6: =TEXT(C6,"0.00")&"–"&TEXT(D6,"0.00") -> 95.88–97.04 | B6: =COUNTIFS('Raw Data'!$H$2:$H$1001,">="&C6,'Raw Data'!$H$2:$H$1001,"<"&D6) -> 126 | C6: =D5 -> 95.875 | D6: =$L$1+(4)*($N$1-$L$1)/6 -> 97.041667
A7: =TEXT(C7,"0.00")&"–"&TEXT(D7,"0.00") -> 97.04–98.21 | B7: =COUNTIFS('Raw Data'!$H$2:$H$1001,">="&C7,'Raw Data'!$H$2:$H$1001,"<"&D7) -> 19 | C7: =D6 -> 97.041667 | D7: =$L$1+(5)*($N$1-$L$1)/6 -> 98.208333
A8: =TEXT(C8,"0.00")&"–"&TEXT(D8,"0.00") -> 98.21–99.38 | B8: =COUNTIFS('Raw Data'!$H$2:$H$1001,">="&C8,'Raw Data'!$H$2:$H$1001,"<="&D8) -> 10 | C8: =D7 -> 98.208333 | D8: =$N$1 -> 99.375
A9: ="> "&TEXT(C9,"0.00")&" (above fence)" -> > 99.38 (above fence) | B9: =COUNTIFS('Raw Data'!$H$2:$H$1001,">"&C9,'Raw Data'!$H$2:$H$1001,"<="&D9) -> 196 | C9: =$N$1 -> 99.375 | D9: =MAX('Raw Data'!$H$2:$H$1001) -> 8758
A11: IQR Outlier Fence Summary
A12: Lower Limit (Q1 − 1.5×IQR) | B12: =G1 -> 92.375
A13: Upper Limit (Q3 + 1.5×IQR) | B13: =I1 -> 99.375
A14: Count below lower limit | B14: =B2 -> 94
A15: Count above upper limit | B15: =B9 -> 196
A16: % flagged as outliers | B16: =(B2+B9)/SUM(B2:B9) -> 0.29145729

Sheet Plot of Variable_5
A1: Launch Mass (kg) — bin range | B1: Count of Satellites | C1: Bin lower (>=) | D1: Bin upper | F1: Lower Limit: | G1: ='Central Tendency & Dispersion'!$AB$8 -> -65 | H1: Upper Limit: | I1: ='Central Tendency & Dispersion'!$AC$8 -> 503 | K1: Eff. Lower: | L1: =MAX($G$1,MIN('Raw Data'!$I$2:$I$1001)) -> 1 | M1: Eff. Upper: | N1: =MIN($I$1,MAX('Raw Data'!$I$2:$I$1001)) -> 503
A2: ="< "&TEXT(D2,"#,##0")&" (below fence)" -> < 1 (below fence) | B2: =COUNTIFS('Raw Data'!$I$2:$I$1001,">="&C2,'Raw Data'!$I$2:$I$1001,"<"&D2) -> 0 | C2: =MIN('Raw Data'!$I$2:$I$1001) -> 1 | D2: =$L$1 -> 1
A3: =TEXT(C3,"#,##0")&"–"&TEXT(D3,"#,##0") -> 1–85 | B3: =COUNTIFS('Raw Data'!$I$2:$I$1001,">="&C3,'Raw Data'!$I$2:$I$1001,"<"&D3) -> 185 | C3: =D2 -> 1 | D3: =$L$1+(1)*($N$1-$L$1)/6 -> 84.666667
A4: =TEXT(C4,"#,##0")&"–"&TEXT(D4,"#,##0") -> 85–168 | B4: =COUNTIFS('Raw Data'!$I$2:$I$1001,">="&C4,'Raw Data'!$I$2:$I$1001,"<"&D4) -> 86 | C4: =D3 -> 84.666667 | D4: =$L$1+(2)*($N$1-$L$1)/6 -> 168.33333
A5: =TEXT(C5,"#,##0")&"–"&TEXT(D5,"#,##0") -> 168–252 | B5: =COUNTIFS('Raw Data'!$I$2:$I$1001,">="&C5,'Raw Data'!$I$2:$I$1001,"<"&D5) -> 68 | C5: =D4 -> 168.33333 | D5: =$L$1+(3)*($N$1-$L$1)/6 -> 252
A6: =TEXT(C6,"#,##0")&"–"&TEXT(D6,"#,##0") -> 252–336 | B6: =COUNTIFS('Raw Data'!$I$2:$I$1001,">="&C6,'Raw Data'!$I$2:$I$1001,"<"&D6) -> 444 | C6: =D5 -> 252 | D6: =$L$1+(4)*($N$1-$L$1)/6 -> 335.66667
A7: =TEXT(C7,"#,##0")&"–"&TEXT(D7,"#,##0") -> 336–419 | B7: =COUNTIFS('Raw Data'!$I$2:$I$1001,">="&C7,'Raw Data'!$I$2:$I$1001,"<"&D7) -> 5 | C7: =D6 -> 335.66667 | D7: =$L$1+(5)*($N$1-$L$1)/6 -> 419.33333
A8: =TEXT(C8,"#,##0")&"–"&TEXT(D8,"#,##0") -> 419–503 | B8: =COUNTIFS('Raw Data'!$I$2:$I$1001,">="&C8,'Raw Data'!$I$2:$I$1001,"<="&D8) -> 4 | C8: =D7 -> 419.33333 | D8: =$N$1 -> 503
A9: ="> "&TEXT(C9,"#,##0")&" (above fence)" -> > 503 (above fence) | B9: =COUNTIFS('Raw Data'!$I$2:$I$1001,">"&C9,'Raw Data'!$I$2:$I$1001,"<="&D9) -> 175 | C9: =$N$1 -> 503 | D9: =MAX('Raw Data'!$I$2:$I$1001) -> 20000
A11: IQR Outlier Fence Summary
A12: Lower Limit (Q1 − 1.5×IQR) | B12: =G1 -> -65
A13: Upper Limit (Q3 + 1.5×IQR) | B13: =I1 -> 503
A14: Count below lower limit | B14: =B2 -> 0
A15: Count above upper limit | B15: =B9 -> 175
A16: % flagged as outliers | B16: =(B2+B9)/SUM(B2:B9) -> 0.18097208

Sheet Plot of Variable_6
A1: Country | B1: Count
A2: =INDEX('Central Tendency & Dispersion'!$N$2:$N$54,MATCH(1,'Central Tendency & Dispersion'!$P$2:$P$54,0)) -> USA | B2: =INDEX('Central Tendency & Dispersion'!$O$2:$O$54,MATCH(1,'Central Tendency & Dispersion'!$P$2:$P$54,0)) -> 669
A3: =INDEX('Central Tendency & Dispersion'!$N$2:$N$54,MATCH(2,'Central Tendency & Dispersion'!$P$2:$P$54,0)) -> United Kingdom | B3: =INDEX('Central Tendency & Dispersion'!$O$2:$O$54,MATCH(2,'Central Tendency & Dispersion'!$P$2:$P$54,0)) -> 85
A4: =INDEX('Central Tendency & Dispersion'!$N$2:$N$54,MATCH(3,'Central Tendency & Dispersion'!$P$2:$P$54,0)) -> China | B4: =INDEX('Central Tendency & Dispersion'!$O$2:$O$54,MATCH(3,'Central Tendency & Dispersion'!$P$2:$P$54,0)) -> 77
A5: =INDEX('Central Tendency & Dispersion'!$N$2:$N$54,MATCH(4,'Central Tendency & Dispersion'!$P$2:$P$54,0)) -> Russia | B5: =INDEX('Central Tendency & Dispersion'!$O$2:$O$54,MATCH(4,'Central Tendency & Dispersion'!$P$2:$P$54,0)) -> 30
A6: =INDEX('Central Tendency & Dispersion'!$N$2:$N$54,MATCH(5,'Central Tendency & Dispersion'!$P$2:$P$54,0)) -> Canada | B6: =INDEX('Central Tendency & Dispersion'!$O$2:$O$54,MATCH(5,'Central Tendency & Dispersion'!$P$2:$P$54,0)) -> 11
A7: =INDEX('Central Tendency & Dispersion'!$N$2:$N$54,MATCH(6,'Central Tendency & Dispersion'!$P$2:$P$54,0)) -> India | B7: =INDEX('Central Tendency & Dispersion'!$O$2:$O$54,MATCH(6,'Central Tendency & Dispersion'!$P$2:$P$54,0)) -> 11
A8: =INDEX('Central Tendency & Dispersion'!$N$2:$N$54,MATCH(7,'Central Tendency & Dispersion'!$P$2:$P$54,0)) -> Japan | B8: =INDEX('Central Tendency & Dispersion'!$O$2:$O$54,MATCH(7,'Central Tendency & Dispersion'!$P$2:$P$54,0)) -> 11
A9: =INDEX('Central Tendency & Dispersion'!$N$2:$N$54,MATCH(8,'Central Tendency & Dispersion'!$P$2:$P$54,0)) -> Multinational | B9: =INDEX('Central Tendency & Dispersion'!$O$2:$O$54,MATCH(8,'Central Tendency & Dispersion'!$P$2:$P$54,0)) -> 10
A10: =INDEX('Central Tendency & Dispersion'!$N$2:$N$54,MATCH(9,'Central Tendency & Dispersion'!$P$2:$P$54,0)) -> Argentina | B10: =INDEX('Central Tendency & Dispersion'!$O$2:$O$54,MATCH(9,'Central Tendency & Dispersion'!$P$2:$P$54,0)) -> 8
A11: =INDEX('Central Tendency & Dispersion'!$N$2:$N$54,MATCH(10,'Central Tendency & Dispersion'!$P$2:$P$54,0)) -> Luxembourg | B11: =INDEX('Central Tendency & Dispersion'!$O$2:$O$54,MATCH(10,'Central Tendency & Dispersion'!$P$2:$P$54,0)) -> 8
A12: =INDEX('Central Tendency & Dispersion'!$N$2:$N$54,MATCH(11,'Central Tendency & Dispersion'!$P$2:$P$54,0)) -> ESA | B12: =INDEX('Central Tendency & Dispersion'!$O$2:$O$54,MATCH(11,'Central Tendency & Dispersion'!$P$2:$P$54,0)) -> 7
A13: =INDEX('Central Tendency & Dispersion'!$N$2:$N$54,MATCH(12,'Central Tendency & Dispersion'!$P$2:$P$54,0)) -> Germany | B13: =INDEX('Central Tendency & Dispersion'!$O$2:$O$54,MATCH(12,'Central Tendency & Dispersion'!$P$2:$P$54,0)) -> 5
A14: =INDEX('Central Tendency & Dispersion'!$N$2:$N$54,MATCH(13,'Central Tendency & Dispersion'!$P$2:$P$54,0)) -> Australia | B14: =INDEX('Central Tendency & Dispersion'!$O$2:$O$54,MATCH(13,'Central Tendency & Dispersion'!$P$2:$P$54,0)) -> 4
A15: =INDEX('Central Tendency & Dispersion'!$N$2:$N$54,MATCH(14,'Central Tendency & Dispersion'!$P$2:$P$54,0)) -> Brazil | B15: =INDEX('Central Tendency & Dispersion'!$O$2:$O$54,MATCH(14,'Central Tendency & Dispersion'!$P$2:$P$54,0)) -> 4
A16: =INDEX('Central Tendency & Dispersion'!$N$2:$N$54,MATCH(15,'Central Tendency & Dispersion'!$P$2:$P$54,0)) -> France | B16: =INDEX('Central Tendency & Dispersion'!$O$2:$O$54,MATCH(15,'Central Tendency & Dispersion'!$P$2:$P$54,0)) -> 4
A17: ="Other ("&(COUNTA('Central Tendency & Dispersion'!$N$2:$N$54)-15)&" countries)" -> Other (38 countries) | B17: =SUM('Central Tendency & Dispersion'!$O$2:$O$54)-SUM(B2:B16) -> 56

Sheet Plot of Variable_7
A1: Users | B1: Count
A2: =INDEX('Central Tendency & Dispersion'!$Q$2:$Q$13,MATCH(1,'Central Tendency & Dispersion'!$S$2:$S$13,0)) -> Commercial | B2: =INDEX('Central Tendency & Dispersion'!$R$2:$R$13,MATCH(1,'Central Tendency & Dispersion'!$S$2:$S$13,0)) -> 788
A3: =INDEX('Central Tendency & Dispersion'!$Q$2:$Q$13,MATCH(2,'Central Tendency & Dispersion'!$S$2:$S$13,0)) -> Government | B3: =INDEX('Central Tendency & Dispersion'!$R$2:$R$13,MATCH(2,'Central Tendency & Dispersion'!$S$2:$S$13,0)) -> 80
A4: =INDEX('Central Tendency & Dispersion'!$Q$2:$Q$13,MATCH(3,'Central Tendency & Dispersion'!$S$2:$S$13,0)) -> Military | B4: =INDEX('Central Tendency & Dispersion'!$R$2:$R$13,MATCH(3,'Central Tendency & Dispersion'!$S$2:$S$13,0)) -> 58
A5: =INDEX('Central Tendency & Dispersion'!$Q$2:$Q$13,MATCH(4,'Central Tendency & Dispersion'!$S$2:$S$13,0)) -> Civil | B5: =INDEX('Central Tendency & Dispersion'!$R$2:$R$13,MATCH(4,'Central Tendency & Dispersion'!$S$2:$S$13,0)) -> 33
A6: =INDEX('Central Tendency & Dispersion'!$Q$2:$Q$13,MATCH(5,'Central Tendency & Dispersion'!$S$2:$S$13,0)) -> Government/Commercial | B6: =INDEX('Central Tendency & Dispersion'!$R$2:$R$13,MATCH(5,'Central Tendency & Dispersion'!$S$2:$S$13,0)) -> 12
A7: =INDEX('Central Tendency & Dispersion'!$Q$2:$Q$13,MATCH(6,'Central Tendency & Dispersion'!$S$2:$S$13,0)) -> Military/Commercial | B7: =INDEX('Central Tendency & Dispersion'!$R$2:$R$13,MATCH(6,'Central Tendency & Dispersion'!$S$2:$S$13,0)) -> 12
A8: =INDEX('Central Tendency & Dispersion'!$Q$2:$Q$13,MATCH(7,'Central Tendency & Dispersion'!$S$2:$S$13,0)) -> Government/Civil | B8: =INDEX('Central Tendency & Dispersion'!$R$2:$R$13,MATCH(7,'Central Tendency & Dispersion'!$S$2:$S$13,0)) -> 6
A9: =INDEX('Central Tendency & Dispersion'!$Q$2:$Q$13,MATCH(8,'Central Tendency & Dispersion'!$S$2:$S$13,0)) -> Military/Government | B9: =INDEX('Central Tendency & Dispersion'!$R$2:$R$13,MATCH(8,'Central Tendency & Dispersion'!$S$2:$S$13,0)) -> 6
A10: =INDEX('Central Tendency & Dispersion'!$Q$2:$Q$13,MATCH(9,'Central Tendency & Dispersion'!$S$2:$S$13,0)) -> Military/Civil | B10: =INDEX('Central Tendency & Dispersion'!$R$2:$R$13,MATCH(9,'Central Tendency & Dispersion'!$S$2:$S$13,0)) -> 2
A11: =INDEX('Central Tendency & Dispersion'!$Q$2:$Q$13,MATCH(10,'Central Tendency & Dispersion'!$S$2:$S$13,0)) -> Civil/Government | B11: =INDEX('Central Tendency & Dispersion'!$R$2:$R$13,MATCH(10,'Central Tendency & Dispersion'!$S$2:$S$13,0)) -> 1
A12: =INDEX('Central Tendency & Dispersion'!$Q$2:$Q$13,MATCH(11,'Central Tendency & Dispersion'!$S$2:$S$13,0)) -> Civil/Military | B12: =INDEX('Central Tendency & Dispersion'!$R$2:$R$13,MATCH(11,'Central Tendency & Dispersion'!$S$2:$S$13,0)) -> 1
A13: =INDEX('Central Tendency & Dispersion'!$Q$2:$Q$13,MATCH(12,'Central Tendency & Dispersion'!$S$2:$S$13,0)) -> Government/Military | B13: =INDEX('Central Tendency & Dispersion'!$R$2:$R$13,MATCH(12,'Central Tendency & Dispersion'!$S$2:$S$13,0)) -> 1

Sheet Plot of Variable_8
A1: Purpose | B1: Count
A2: =INDEX('Central Tendency & Dispersion'!$T$2:$T$18,MATCH(1,'Central Tendency & Dispersion'!$V$2:$V$18,0)) -> Communications | B2: =INDEX('Central Tendency & Dispersion'!$U$2:$U$18,MATCH(1,'Central Tendency & Dispersion'!$V$2:$V$18,0)) -> 704
A3: =INDEX('Central Tendency & Dispersion'!$T$2:$T$18,MATCH(2,'Central Tendency & Dispersion'!$V$2:$V$18,0)) -> Earth Observation | B3: =INDEX('Central Tendency & Dispersion'!$U$2:$U$18,MATCH(2,'Central Tendency & Dispersion'!$V$2:$V$18,0)) -> 174
A4: =INDEX('Central Tendency & Dispersion'!$T$2:$T$18,MATCH(3,'Central Tendency & Dispersion'!$V$2:$V$18,0)) -> Technology Development | B4: =INDEX('Central Tendency & Dispersion'!$U$2:$U$18,MATCH(3,'Central Tendency & Dispersion'!$V$2:$V$18,0)) -> 53
A5: =INDEX('Central Tendency & Dispersion'!$T$2:$T$18,MATCH(4,'Central Tendency & Dispersion'!$V$2:$V$18,0)) -> Navigation/Global Positioning | B5: =INDEX('Central Tendency & Dispersion'!$U$2:$U$18,MATCH(4,'Central Tendency & Dispersion'!$V$2:$V$18,0)) -> 20
A6: =INDEX('Central Tendency & Dispersion'!$T$2:$T$18,MATCH(5,'Central Tendency & Dispersion'!$V$2:$V$18,0)) -> Space Science | B6: =INDEX('Central Tendency & Dispersion'!$U$2:$U$18,MATCH(5,'Central Tendency & Dispersion'!$V$2:$V$18,0)) -> 18
A7: =INDEX('Central Tendency & Dispersion'!$T$2:$T$18,MATCH(6,'Central Tendency & Dispersion'!$V$2:$V$18,0)) -> Technology Demonstration | B7: =INDEX('Central Tendency & Dispersion'!$U$2:$U$18,MATCH(6,'Central Tendency & Dispersion'!$V$2:$V$18,0)) -> 12
A8: =INDEX('Central Tendency & Dispersion'!$T$2:$T$18,MATCH(7,'Central Tendency & Dispersion'!$V$2:$V$18,0)) -> Navigation/Regional Positioning | B8: =INDEX('Central Tendency & Dispersion'!$U$2:$U$18,MATCH(7,'Central Tendency & Dispersion'!$V$2:$V$18,0)) -> 3
A9: =INDEX('Central Tendency & Dispersion'!$T$2:$T$18,MATCH(8,'Central Tendency & Dispersion'!$V$2:$V$18,0)) -> Surveillance | B9: =INDEX('Central Tendency & Dispersion'!$U$2:$U$18,MATCH(8,'Central Tendency & Dispersion'!$V$2:$V$18,0)) -> 3
A10: =INDEX('Central Tendency & Dispersion'!$T$2:$T$18,MATCH(9,'Central Tendency & Dispersion'!$V$2:$V$18,0)) -> Communications/Maritime Tracking | B10: =INDEX('Central Tendency & Dispersion'!$U$2:$U$18,MATCH(9,'Central Tendency & Dispersion'!$V$2:$V$18,0)) -> 2
A11: =INDEX('Central Tendency & Dispersion'!$T$2:$T$18,MATCH(10,'Central Tendency & Dispersion'!$V$2:$V$18,0)) -> Earth Observation/Technology Development | B11: =INDEX('Central Tendency & Dispersion'!$U$2:$U$18,MATCH(10,'Central Tendency & Dispersion'!$V$2:$V$18,0)) -> 2
A12: =INDEX('Central Tendency & Dispersion'!$T$2:$T$18,MATCH(11,'Central Tendency & Dispersion'!$V$2:$V$18,0)) -> Earth Science | B12: =INDEX('Central Tendency & Dispersion'!$U$2:$U$18,MATCH(11,'Central Tendency & Dispersion'!$V$2:$V$18,0)) -> 2
A13: =INDEX('Central Tendency & Dispersion'!$T$2:$T$18,MATCH(12,'Central Tendency & Dispersion'!$V$2:$V$18,0)) -> Meteorological | B13: =INDEX('Central Tendency & Dispersion'!$U$2:$U$18,MATCH(12,'Central Tendency & Dispersion'!$V$2:$V$18,0)) -> 2
A14: =INDEX('Central Tendency & Dispersion'!$T$2:$T$18,MATCH(13,'Central Tendency & Dispersion'!$V$2:$V$18,0)) -> Earth Observation | B14: =INDEX('Central Tendency & Dispersion'!$U$2:$U$18,MATCH(13,'Central Tendency & Dispersion'!$V$2:$V$18,0)) -> 1
A15: =INDEX('Central Tendency & Dispersion'!$T$2:$T$18,MATCH(14,'Central Tendency & Dispersion'!$V$2:$V$18,0)) -> Earth Science/Earth Observation | B15: =INDEX('Central Tendency & Dispersion'!$U$2:$U$18,MATCH(14,'Central Tendency & Dispersion'!$V$2:$V$18,0)) -> 1
A16: =INDEX('Central Tendency & Dispersion'!$T$2:$T$18,MATCH(15,'Central Tendency & Dispersion'!$V$2:$V$18,0)) -> Mission Extension Technology | B16: =INDEX('Central Tendency & Dispersion'!$U$2:$U$18,MATCH(15,'Central Tendency & Dispersion'!$V$2:$V$18,0)) -> 1
A17: =INDEX('Central Tendency & Dispersion'!$T$2:$T$18,MATCH(16,'Central Tendency & Dispersion'!$V$2:$V$18,0)) -> Satellite Positioning | B17: =INDEX('Central Tendency & Dispersion'!$U$2:$U$18,MATCH(16,'Central Tendency & Dispersion'!$V$2:$V$18,0)) -> 1
A18: =INDEX('Central Tendency & Dispersion'!$T$2:$T$18,MATCH(17,'Central Tendency & Dispersion'!$V$2:$V$18,0)) -> Unknown | B18: =INDEX('Central Tendency & Dispersion'!$U$2:$U$18,MATCH(17,'Central Tendency & Dispersion'!$V$2:$V$18,0)) -> 1

Sheet Categorical Association
A1: Two categorical variables: Users and Purpose. Counts below are live COUNTIFS formulas against Raw Data.
A3: Purpose \ Users | B3: Commercial | C3: Government | D3: Military | E3: Civil | F3: Other
A4: Communications | B4: =COUNTIFS('Raw Data'!$D$2:$D$1001,$A4,'Raw Data'!$C$2:$C$1001,B$3) -> 661 | C4: =COUNTIFS('Raw Data'!$D$2:$D$1001,$A4,'Raw Data'!$C$2:$C$1001,C$3) -> 14 | D4: =COUNTIFS('Raw Data'!$D$2:$D$1001,$A4,'Raw Data'!$C$2:$C$1001,D$3) -> 13 | E4: =COUNTIFS('Raw Data'!$D$2:$D$1001,$A4,'Raw Data'!$C$2:$C$1001,E$3) -> 4 | F4: =COUNTIF('Raw Data'!$D$2:$D$1001,$A4)-SUM(B4:E4) -> 12
A5: Earth Observation | B5: =COUNTIFS('Raw Data'!$D$2:$D$1001,$A5,'Raw Data'!$C$2:$C$1001,B$3) -> 93 | C5: =COUNTIFS('Raw Data'!$D$2:$D$1001,$A5,'Raw Data'!$C$2:$C$1001,C$3) -> 38 | D5: =COUNTIFS('Raw Data'!$D$2:$D$1001,$A5,'Raw Data'!$C$2:$C$1001,D$3) -> 32 | E5: =COUNTIFS('Raw Data'!$D$2:$D$1001,$A5,'Raw Data'!$C$2:$C$1001,E$3) -> 5 | F5: =COUNTIF('Raw Data'!$D$2:$D$1001,$A5)-SUM(B5:E5) -> 6
A6: Navigation/Global Positioning | B6: =COUNTIFS('Raw Data'!$D$2:$D$1001,$A6,'Raw Data'!$C$2:$C$1001,B$3) -> 4 | C6: =COUNTIFS('Raw Data'!$D$2:$D$1001,$A6,'Raw Data'!$C$2:$C$1001,C$3) -> 0 | D6: =COUNTIFS('Raw Data'!$D$2:$D$1001,$A6,'Raw Data'!$C$2:$C$1001,D$3) -> 0 | E6: =COUNTIFS('Raw Data'!$D$2:$D$1001,$A6,'Raw Data'!$C$2:$C$1001,E$3) -> 0 | F6: =COUNTIF('Raw Data'!$D$2:$D$1001,$A6)-SUM(B6:E6) -> 16
A7: Technology Development | B7: =COUNTIFS('Raw Data'!$D$2:$D$1001,$A7,'Raw Data'!$C$2:$C$1001,B$3) -> 14 | C7: =COUNTIFS('Raw Data'!$D$2:$D$1001,$A7,'Raw Data'!$C$2:$C$1001,C$3) -> 9 | D7: =COUNTIFS('Raw Data'!$D$2:$D$1001,$A7,'Raw Data'!$C$2:$C$1001,D$3) -> 11 | E7: =COUNTIFS('Raw Data'!$D$2:$D$1001,$A7,'Raw Data'!$C$2:$C$1001,E$3) -> 15 | F7: =COUNTIF('Raw Data'!$D$2:$D$1001,$A7)-SUM(B7:E7) -> 4
A10: % within Purpose | B10: Commercial | C10: Government | D10: Military | E10: Civil | F10: Other
A11: =A4 -> Communications | B11: =B4/SUM($B4:$F4)*100 -> 93.892045 | C11: =C4/SUM($B4:$F4)*100 -> 1.9886364 | D11: =D4/SUM($B4:$F4)*100 -> 1.8465909 | E11: =E4/SUM($B4:$F4)*100 -> 0.56818182 | F11: =F4/SUM($B4:$F4)*100 -> 1.7045455
A12: =A5 -> Earth Observation | B12: =B5/SUM($B5:$F5)*100 -> 53.448276 | C12: =C5/SUM($B5:$F5)*100 -> 21.83908 | D12: =D5/SUM($B5:$F5)*100 -> 18.390805 | E12: =E5/SUM($B5:$F5)*100 -> 2.8735632 | F12: =F5/SUM($B5:$F5)*100 -> 3.4482759
A13: =A6 -> Navigation/Global Positioning | B13: =B6/SUM($B6:$F6)*100 -> 20 | C13: =C6/SUM($B6:$F6)*100 -> 0 | D13: =D6/SUM($B6:$F6)*100 -> 0 | E13: =E6/SUM($B6:$F6)*100 -> 0 | F13: =F6/SUM($B6:$F6)*100 -> 80
A14: =A7 -> Technology Development | B14: =B7/SUM($B7:$F7)*100 -> 26.415094 | C14: =C7/SUM($B7:$F7)*100 -> 16.981132 | D14: =D7/SUM($B7:$F7)*100 -> 20.754717 | E14: =E7/SUM($B7:$F7)*100 -> 28.301887 | F14: =F7/SUM($B7:$F7)*100 -> 7.5471698
A16: The 100% stacked bar chart (see 'Plot of Association' tab) shows Purpose and Users are not independent. Communications satellites are overwhelmingly Commercial — look at row 1's percentage vs the other rows. Navigation satellites lean heavily toward 'Other' users rather than Commercial, while Earth Observation is more evenly mixed across Commercial, Government, and Military. Technology Development satellites are the most evenly spread across all user types. All percentages update live if the underlying Raw Data changes.

Sheet Plot of Association
A1: Purpose | B1: Commercial | C1: Government | D1: Military | E1: Civil | F1: Other
A2: ='Categorical Association'!A11 -> Communications | B2: ='Categorical Association'!B11 -> 93.892045 | C2: ='Categorical Association'!C11 -> 1.9886364 | D2: ='Categorical Association'!D11 -> 1.8465909 | E2: ='Categorical Association'!E11 -> 0.56818182 | F2: ='Categorical Association'!F11 -> 1.7045455
A3: ='Categorical Association'!A12 -> Earth Observation | B3: ='Categorical Association'!B12 -> 53.448276 | C3: ='Categorical Association'!C12 -> 21.83908 | D3: ='Categorical Association'!D12 -> 18.390805 | E3: ='Categorical Association'!E12 -> 2.8735632 | F3: ='Categorical Association'!F12 -> 3.4482759
A4: ='Categorical Association'!A13 -> Navigation/Global Positioning | B4: ='Categorical Association'!B13 -> 20 | C4: ='Categorical Association'!C13 -> 0 | D4: ='Categorical Association'!D13 -> 0 | E4: ='Categorical Association'!E13 -> 0 | F4: ='Categorical Association'!F13 -> 80
A5: ='Categorical Association'!A14 -> Technology Development | B5: ='Categorical Association'!B14 -> 26.415094 | C5: ='Categorical Association'!C14 -> 16.981132 | D5: ='Categorical Association'!D14 -> 20.754717 | E5: ='Categorical Association'!E14 -> 28.301887 | F5: ='Categorical Association'!F14 -> 7.5471698

Sheet Plot of Scatter (X1 vs X2)
A1: Scatter references 'Raw Data'!E2:E1001 (Perigee, X1) and 'Raw Data'!F2:F1001 (Apogee, X2) directly — no data copied.
A30: Insight (from the scatter plot itself):
A31: The scatter plot shows a clear positive relationship: as Perigee increases, Apogee tends to increase too. Most points cluster tightly along a diagonal band close to the line Apogee = Perigee, especially in the lower-left region (under ~1000 km) — this is the dense cloud of near-circular low-Earth-orbit satellites, where perigee and apogee are almost equal by definition. A smaller number of points fan out well above that diagonal, corresponding to satellites in more elliptical orbits where apogee is noticeably larger than perigee. There are no points below the diagonal, which makes physical sense — apogee (farthest point) can never be smaller than perigee (closest point) for a given orbit. Overall the visualization suggests a moderately strong, positive, and roughly linear association for the bulk of the data, with a distinct outlier group of highly elliptical orbits pulling the relationship away from a perfect straight line.

Sheet Covariance & Correlation
A1: Selected variables: X1 = Perigee (km), X2 = Apogee (km). Both values below are live formulas referencing Raw Data directly.
A3: Statistic | B3: Value
A4: n (paired observations) | B4: =SUMPRODUCT(--(ISNUMBER('Raw Data'!$E$2:$E$1001)),--(ISNUMBER('Raw Data'!$F$2:$F$1001))) -> 999
A5: Covariance (X1, X2) | B5: =_xlfn.COVARIANCE.S('Raw Data'!$E$2:$E$1001,'Raw Data'!$F$2:$F$1001) -> 1.2048372e+08
A6: Correlation coefficient (r) | B6: =CORREL('Raw Data'!$E$2:$E$1001,'Raw Data'!$F$2:$F$1001) -> 0.62088442
A7: The covariance between Perigee and Apogee is positive (see B5), meaning the two variables tend to move in the same direction — satellites with a higher perigee also tend to have a higher apogee. Because covariance's magnitude depends on the units and scale of the variables (km² here), it's hard to judge strength directly from it alone, which is why correlation is more useful. The Pearson correlation coefficient (B6) indicates a moderately strong positive linear relationship. This makes physical sense: perigee and apogee together define a satellite's orbit shape, so satellites in near-circular orbits naturally have perigee approximately equal to apogee, pulling the correlation upward. The correlation isn't closer to 1 because a subset of satellites are in highly elliptical orbits, where apogee can be dramatically larger than perigee — these cases add scatter around the otherwise tight near-circular cluster visible in the scatter plot tab.
